Traceback (most recent call last):
  File "C:\Users\Matt\Desktop\foundryBackup\Main.py", line 3, in <module>
    from google.oauth2.credentials import Credentials
ModuleNotFoundError: No module named 'google'
Traceback (most recent call last):
  File "C:\Users\Matt\Desktop\foundryBackup\Main.py", line 3, in <module>
    from google.oauth2.credentials import Credentials
ModuleNotFoundError: No module named 'google'
Traceback (most recent call last):
  File "C:\Users\Matt\Desktop\foundryBackup\Main.py", line 3, in <module>
    from google.oauth2.credentials import Credentials
ModuleNotFoundError: No module named 'google'
Checking path if valid...
Valid backup path! Zipping files...
--------------------
File zipped as foundry_backup_2024-02-12_15-04-40.zip!
--------------------
Traceback (most recent call last):
  File "C:\Users\Matt\Desktop\foundryBackup\Main.py", line 109, in <module>
    main()
  File "C:\Users\Matt\Desktop\foundryBackup\Main.py", line 30, in main
    drive_service = authenticate_google_drive()
                    ^^^^^^^^^^^^^^^^^^^^^^^^^^^
  File "C:\Users\Matt\Desktop\foundryBackup\Main.py", line 99, in authenticate_google_drive
    creds.refresh(Request())
                  ^^^^^^^
NameError: name 'Request' is not defined
